<?xml version="1.0" encoding="utf-8"?>
<!-- This URDF was automatically generated by SolidWorks to URDF Exporter! -->
<robot name="fa_robot">
  <mujoco>
        <compiler 
        meshdir="../meshes/" 
        balanceinertia="true" 
        discardvisual="false" />
  </mujoco>  
  <link name="pelvis">
    <inertial>
      <origin xyz="0.0085179421 -0.0017788117 0.39637073" rpy="0 0 0" />
      <mass value="43.941407" />
      <inertia ixx="1.9983651" ixy="0.0030277999" ixz="0.058369786" 
               iyy="1.8620078" iyz="0.014352137" izz="0.36423365" />
    </inertial>
    <visual>
      <origin xyz="0 0 0" rpy="0 0 0" />
      <geometry>
        <mesh filename="../meshes/pelvis_combined.stl" />
      </geometry>
      <material name="">
        <color rgba="1 1 1 1" />
      </material>
    </visual>
    <collision>
      <origin xyz="0 0 0" rpy="0 0 0" />
      <geometry>
        <mesh filename="../meshes/pelvis.STL" />
      </geometry>
    </collision>
  </link>

  <link name="left_hip_pitch_link">
    <inertial>
      <origin xyz="0.0085179421 -0.0017788117 0.39637073" rpy="0 0 0" />
      <mass value="43.941407" />
      <inertia ixx="1.9983651" ixy="0.0030277999" ixz="0.058369786" 
               iyy="1.8620078" iyz="0.014352137" izz="0.36423365" />
    </inertial>
    <visual>
      <origin xyz="0 0 0" rpy="0 0 0" />
      <geometry>
        <mesh filename="../meshes/pelvis_combined.stl" />
      </geometry>
      <material name="">
        <color rgba="1 1 1 1" />
      </material>
    </visual>
    <collision>
      <origin xyz="0 0 0" rpy="0 0 0" />
      <geometry>
        <mesh filename="../meshes/pelvis.STL" />
      </geometry>
    </collision>
  </link>
  <joint name="left_hip_pitch_joint" type="revolute">
    <origin xyz="0 0.085459 0.085352" rpy="-0.3927 0 0" />
    <parent link="pelvis" />
    <child link="left_hip_pitch_link" />
    <axis xyz="0 1 0" />
    <limit lower="-2.09" upper="2.09" effort="0" velocity="0" />
  </joint>

</robot>