<?xml version="1.0" encoding="utf-8"?>
<!-- This URDF was automatically generated by SolidWorks to URDF Exporter! -->
<robot name="fa_robot">
  <mujoco>
        <compiler 
        meshdir="../meshes/" 
        balanceinertia="true" 
        discardvisual="false" />
  </mujoco>  
  <link name="pelvis">
    <inertial>
      <origin xyz="0.0085179421 -0.0017788117 0.39637073" rpy="0 0 0" />
      <mass value="43.941407" />
      <inertia ixx="1.9983651" ixy="0.0030277999" ixz="0.058369786" 
               iyy="1.8620078" iyz="0.014352137" izz="0.36423365" />
    </inertial>
    <visual>
      <origin xyz="0 0 0" rpy="0 0 0" />
      <geometry>
        <mesh filename="../meshes/pelvis_combined.stl" />
      </geometry>
      <material name="">
        <color rgba="1 1 1 1" />
      </material>
    </visual>
    <collision>
      <origin xyz="0 0 0" rpy="0 0 0" />
      <geometry>
        <mesh filename="../meshes/pelvis.STL" />
      </geometry>
    </collision>
  </link>

  <link name="left_hip_pitch_link">
    <inertial>
      <origin xyz="-0.00654480 0.07405720 -0.02844697" rpy="0 0 0" />
      <mass value="3.10267723" />
      <inertia ixx="0.00932967" ixy="0.00010123" ixz="-0.00006312" iyy="0.00703202" iyz="0.00030904"
        izz="0.00734799" />
    </inertial>
    <visual>
      <origin xyz="0 0 0" rpy="0 0 0" />
      <geometry>
        <mesh filename="../meshes/left_hip_pitch_link.STL" />
      </geometry>
      <material name="">
        <color rgba="0.792156862745098 0.819607843137255 0.933333333333333 1" />
      </material>
    </visual>
    <collision>
      <origin xyz="0 0 0" rpy="0 0 0" />
      <geometry>
        <mesh filename="../meshes/left_hip_pitch_link.STL" />
      </geometry>
    </collision>
  </link>
  <joint name="left_hip_pitch_joint" type="revolute">
    <origin xyz="0 0.085459 0.085352" rpy="-0.3927 0 0" />
    <parent link="pelvis" />
    <child link="left_hip_pitch_link" />
    <axis xyz="0 1 0" />
    <limit lower="-2.09" upper="2.09" effort="0" velocity="0" />
  </joint>

  <link name="left_hip_roll_link">
    <inertial>
      <origin xyz="-0.00336185 -0.00004279 -0.07811160" rpy="0 0 0" />
      <mass value="2.18995119" />
      <inertia ixx="0.00693445" ixy="0.00000031" ixz="0.00038090" iyy="0.00848650" iyz="-0.00013381"
        izz="0.00638824" />
    </inertial>
    <visual>
      <origin xyz="0 0 0" rpy="0 0 0" />
      <geometry>
        <mesh filename="../meshes/left_hip_roll_link.STL" />
      </geometry>
      <material name="">
        <color rgba="0.866666666666667 0.866666666666667 0.890196078431372 1" />
      </material>
    </visual>
    <collision>
      <origin xyz="0 0 0" rpy="0 0 0" />
      <geometry>
        <mesh filename="../meshes/left_hip_roll_link.STL" />
      </geometry>
    </collision>
  </link>
  <joint name="left_hip_roll_joint" type="revolute">
    <origin xyz="0 0.076873 -0.029999" rpy="0.3927 0 0" />
    <parent link="left_hip_pitch_link" />
    <child link="left_hip_roll_link" />
    <axis xyz="1 0 0" />
    <limit lower="-0.52" upper="2.62" effort="0" velocity="0" />
  </joint>

  <link name="left_hip_yaw_link">
    <inertial>
      <origin xyz="0.00198226 -0.01634818 -0.08391807" rpy="0 0 0" />
      <mass value="4.38889499" />
      <inertia ixx="0.01929087" ixy="-0.00016796" ixz="0.00029235" iyy="0.01967996" iyz="0.00028777"
        izz="0.01123857" />
    </inertial>
    <visual>
      <origin xyz="0 0 0" rpy="0 0 0" />
      <geometry>
        <mesh filename="../meshes/left_hip_yaw_link.STL" />
      </geometry>
      <material name="">
        <color rgba="0.792156862745098 0.819607843137255 0.933333333333333 1" />
      </material>
    </visual>
    <collision>
      <origin xyz="0 0 0" rpy="0 0 0" />
      <geometry>
        <mesh filename="../meshes/left_hip_yaw_link.STL" />
      </geometry>
    </collision>
  </link>
  <joint name="left_hip_yaw_joint" type="revolute">
    <origin xyz="0 0 -0.13" rpy="0 0 0" />
    <parent link="left_hip_roll_link" />
    <child link="left_hip_yaw_link" />
    <axis xyz="0 0 1" />
    <limit lower="-0.79" upper="0.79" effort="0" velocity="0" />
  </joint>

  <link name="left_knee_link">
    <inertial>
      <origin xyz="0.00254924 0.00073851 -0.15994600" rpy="0 0 0" />
      <mass value="4.37702759" />
      <inertia ixx="0.05805838" ixy="0.00009690" ixz="-0.00526828" iyy="0.05953803"
        iyz="-0.00127194" izz="0.00670100" />
    </inertial>
    <visual>
      <origin xyz="0 0 0" rpy="0 0 0" />
      <geometry>
        <mesh filename="../meshes/left_knee_link.STL" />
      </geometry>
      <material name="">
        <color rgba="0.898039215686275 0.917647058823529 0.929411764705882 1" />
      </material>
    </visual>
    <collision>
      <origin xyz="0 0 0" rpy="0 0 0" />
      <geometry>
        <mesh filename="../meshes/left_knee_link.STL" />
      </geometry>
    </collision>
  </link>
  <joint name="left_knee_joint" type="revolute">
    <origin xyz="0 -0.005 -0.208" rpy="0 0 0" />
    <parent link="left_hip_yaw_link" />
    <child link="left_knee_link" />
    <axis xyz="0 1 0" />
    <limit lower="-0.05" upper="2.09" effort="0" velocity="0" />
  </joint>

  <link name="left_ankle_pitch_link">
    <inertial>
      <origin xyz="0.00000000 0.00000000 0.00000000" rpy="0 0 0" />
      <mass value="0.05567491" />
      <inertia ixx="0.00000605" ixy="0.00000000" ixz="0.00000000" iyy="0.00000605" iyz="0.00000000"
        izz="0.00000928" />
    </inertial>
    <visual>
      <origin xyz="0 0 0" rpy="0 0 0" />
      <geometry>
        <mesh filename="../meshes/left_ankle_pitch_link.STL" />
      </geometry>
      <material name="">
        <color rgba="0.686274509803922 0.658823529411765 0.63921568627451 1" />
      </material>
    </visual>
    <collision>
      <origin xyz="0 0 0" rpy="0 0 0" />
      <geometry>
        <mesh filename="../meshes/left_ankle_pitch_link.STL" />
      </geometry>
    </collision>
  </link>
  <joint name="left_ankle_pitch_joint" type="revolute">
    <origin xyz="0 0 -0.42" rpy="0 0 0" />
    <parent link="left_knee_link" />
    <child link="left_ankle_pitch_link" />
    <axis xyz="0 1 0" />
    <limit lower="-1.05" upper="0.52" effort="0" velocity="0" />
  </joint>

  <link name="left_ankle_roll_link">
    <inertial>
      <origin xyz="0.00731163 -0.00000186 -0.02994342" rpy="0 0 0" />
      <mass value="1.17638663" />
      <inertia ixx="0.00157941" ixy="0.00000010" ixz="0.00106696" iyy="0.00622343" iyz="0.00000000"
        izz="0.00617491" />
    </inertial>
    <visual>
      <origin xyz="0 0 0" rpy="0 0 0" />
      <geometry>
        <mesh filename="../meshes/left_ankle_roll_link.STL" />
      </geometry>
      <material name="">
        <color rgba="0.866666666666667 0.866666666666667 0.890196078431372 1" />
      </material>
    </visual>
    <collision>
      <origin xyz="0 0 0" rpy="0 0 0" />
      <geometry>
        <mesh filename="../meshes/left_ankle_roll_link.STL" />
      </geometry>
    </collision>
  </link>
  <joint name="left_ankle_roll_joint" type="revolute">
    <origin xyz="0 0 0" rpy="0 0 0" />
    <parent link="left_ankle_pitch_link" />
    <child link="left_ankle_roll_link" />
    <axis xyz="1 0 0" />
    <limit lower="-0.35" upper="0.35" effort="0" velocity="0" />
  </joint>

  <link name="right_hip_pitch_link">
    <inertial>
      <origin xyz="-0.00654480 -0.07405720 -0.02844697" rpy="0 0 0" />
      <mass value="3.10267723" />
      <inertia ixx="0.00932967" ixy="-0.00010123" ixz="-0.00006312" iyy="0.00703202"
        iyz="-0.00030904" izz="0.00734799" />
    </inertial>
    <visual>
      <origin xyz="0 0 0" rpy="0 0 0" />
      <geometry>
        <mesh filename="../meshes/right_hip_pitch_link.STL" />
      </geometry>
      <material name="">
        <color rgba="0.792156862745098 0.819607843137255 0.933333333333333 1" />
      </material>
    </visual>
    <collision>
      <origin xyz="0 0 0" rpy="0 0 0" />
      <geometry>
        <mesh filename="../meshes/right_hip_pitch_link.STL" />
      </geometry>
    </collision>
  </link>
  <joint name="right_hip_pitch_joint" type="revolute">
    <origin xyz="0 -0.085459 0.085352" rpy="0.3927 0 0" />
    <parent link="pelvis" />
    <child link="right_hip_pitch_link" />
    <axis xyz="0 1 0" />
    <limit lower="-2.09" upper="2.09" effort="0" velocity="0" />
  </joint>

  <link name="right_hip_roll_link">
    <inertial>
      <origin xyz="-0.00336185 0.00004279 -0.07811160" rpy="0 0 0" />
      <mass value="2.18995119" />
      <inertia ixx="0.00693445" ixy="-0.00000031" ixz="0.00038090" iyy="0.00848650" iyz="0.00013381"
        izz="0.00638824" />
    </inertial>
    <visual>
      <origin xyz="0 0 0" rpy="0 0 0" />
      <geometry>
        <mesh filename="../meshes/right_hip_roll_link.STL" />
      </geometry>
      <material name="">
        <color rgba="0.792156862745098 0.819607843137255 0.933333333333333 1" />
      </material>
    </visual>
    <collision>
      <origin xyz="0 0 0" rpy="0 0 0" />
      <geometry>
        <mesh filename="../meshes/right_hip_roll_link.STL" />
      </geometry>
    </collision>
  </link>
  <joint name="right_hip_roll_joint" type="revolute">
    <origin xyz="0 -0.076873 -0.029999" rpy="-0.3927 0 0" />
    <parent link="right_hip_pitch_link" />
    <child link="right_hip_roll_link" />
    <axis xyz="1 0 0" />
    <limit lower="-2.62" upper="0.52" effort="0" velocity="0" />
  </joint>

  <link name="right_hip_yaw_link">
    <inertial>
      <origin xyz="0.00198226 0.01634818 -0.08391807" rpy="0 0 0" />
      <mass value="4.38889499" />
      <inertia ixx="0.01929087" ixy="0.00016796" ixz="0.00029235" iyy="0.01967996" iyz="-0.00028777"
        izz="0.01123857" />
    </inertial>
    <visual>
      <origin xyz="0 0 0" rpy="0 0 0" />
      <geometry>
        <mesh filename="../meshes/right_hip_yaw_link.STL" />
      </geometry>
      <material name="">
        <color rgba="0.792156862745098 0.819607843137255 0.933333333333333 1" />
      </material>
    </visual>
    <collision>
      <origin xyz="0 0 0" rpy="0 0 0" />
      <geometry>
        <mesh filename="../meshes/right_hip_yaw_link.STL" />
      </geometry>
    </collision>
  </link>
  <joint name="right_hip_yaw_joint" type="revolute">
    <origin xyz="0 0 -0.13" rpy="0 0 0" />
    <parent link="right_hip_roll_link" />
    <child link="right_hip_yaw_link" />
    <axis xyz="0 0 1" />
    <limit lower="-0.79" upper="0.79" effort="0" velocity="0" />
  </joint>

  <link name="right_knee_link">
    <inertial>
      <origin xyz="0.00254924 -0.00073851 -0.15994600" rpy="0 0 0" />
      <mass value="4.37702759" />
      <inertia ixx="0.05805838" ixy="-0.00009690" ixz="-0.00526828" iyy="0.05953803"
        iyz="0.00127194" izz="0.006701" />
    </inertial>
    <visual>
      <origin xyz="0 0 0" rpy="0 0 0" />
      <geometry>
        <mesh filename="../meshes/right_knee_link.STL" />
      </geometry>
      <material name="">
        <color rgba="0.898039215686275 0.917647058823529 0.929411764705882 1" />
      </material>
    </visual>
    <collision>
      <origin xyz="0 0 0" rpy="0 0 0" />
      <geometry>
        <mesh filename="../meshes/right_knee_link.STL" />
      </geometry>
    </collision>
  </link>
  <joint name="right_knee_joint" type="revolute">
    <origin xyz="0 0.005 -0.208" rpy="0 0 0" />
    <parent link="right_hip_yaw_link" />
    <child link="right_knee_link" />
    <axis xyz="0 1 0" />
    <limit lower="0.05" upper="2.09" effort="0" velocity="0" />
  </joint>

  <link name="right_ankle_pitch_link">
    <inertial>
      <origin xyz="0.00000000 0.00000000 0.00000000" rpy="0 0 0" />
      <mass value="0.05567491" />
      <inertia ixx="0.00000605" ixy="0.00000000" ixz="0.00000000" iyy="0.00000605" iyz="0.00000000"
        izz="0.00000928" />
    </inertial>
    <visual>
      <origin xyz="0 0 0" rpy="0 0 0" />
      <geometry>
        <mesh filename="../meshes/right_ankle_pitch_link.STL" />
      </geometry>
      <material name="">
        <color rgba="0.686274509803922 0.658823529411765 0.63921568627451 1" />
      </material>
    </visual>
    <collision>
      <origin xyz="0 0 0" rpy="0 0 0" />
      <geometry>
        <mesh filename="../meshes/right_ankle_pitch_link.STL" />
      </geometry>
    </collision>
  </link>
  <joint name="right_ankle_pitch_joint" type="revolute">
    <origin xyz="0 0 -0.42" rpy="0 0 0" />
    <parent link="right_knee_link" />
    <child link="right_ankle_pitch_link" />
    <axis xyz="0 1 0" />
    <limit lower="-1.05" upper="0.52" effort="0" velocity="0" />
  </joint>

  <link name="right_ankle_roll_link">
    <inertial>
      <origin xyz="0.00731163 0.00000186 -0.02994342" rpy="0 0 0" />
      <mass value="1.17638663" />
      <inertia ixx="0.00157941" ixy="-0.00000010" ixz="0.00106696" iyy="0.00622343" iyz="0.00000000"
        izz="0.00617491" />
    </inertial>
    <visual>
      <origin xyz="0 0 0" rpy="0 0 0" />
      <geometry>
        <mesh filename="../meshes/right_ankle_roll_link.STL" />
      </geometry>
      <material name="">
        <color rgba="0.898039215686275 0.917647058823529 0.929411764705882 1" />
      </material>
    </visual>
    <collision>
      <origin xyz="0 0 0" rpy="0 0 0" />
      <geometry>
        <mesh filename="../meshes/right_ankle_roll_link.STL" />
      </geometry>
    </collision>
  </link>
  <joint name="right_ankle_roll_joint" type="revolute">
    <origin xyz="0 0 0" rpy="0 0 0" />
    <parent link="right_ankle_pitch_link" />
    <child link="right_ankle_roll_link" />
    <axis xyz="1 0 0" />
    <limit lower="-0.35" upper="0.35" effort="0" velocity="0" />
  </joint>

  <link name="left_shoulder_pitch_link">
    <inertial>
      <origin xyz="0.00707460 0.03558328 0.00010447" rpy="0 0 0" />
      <mass value="1.98203402" />
      <inertia ixx="0.00322191" ixy="-0.00014609" ixz="0.00002188" iyy="0.00282216" iyz="0.00003695"
        izz="0.00344681" />
    </inertial>
    <visual>
      <origin xyz="0 0 0" rpy="0 0 0" />
      <geometry>
        <mesh filename="../meshes/left_shoulder_pitch_link.STL" />
      </geometry>
      <material name="">
        <color rgba="0.792156862745098 0.819607843137255 0.933333333333333 1" />
      </material>
    </visual>
    <collision>
      <origin xyz="0 0 0" rpy="0 0 0" />
      <geometry>
        <mesh filename="../meshes/left_shoulder_pitch_link.STL" />
      </geometry>
    </collision>
  </link>
  <joint name="left_shoulder_pitch_joint" type="revolute">
    <origin xyz="0.0 0.2153 0.61575" rpy="0 0 0" />
    <parent link="pelvis" />
    <child link="left_shoulder_pitch_link" />
    <axis xyz="0 1 0" />
    <limit lower="-2.79" upper="2.79" effort="0" velocity="0" />
  </joint>

  <link name="left_shoulder_roll_link">
    <inertial>
      <origin xyz="0.00366245 0.00156798 -0.08524724" rpy="0 0 0" />
      <mass value="1.58847867" />
      <inertia ixx="0.00406209" ixy="0.00000975" ixz="-0.00042319" iyy="0.00490117" iyz="0.00003700"
        izz="0.00281181" />
    </inertial>
    <visual>
      <origin xyz="0 0 0" rpy="0 0 0" />
      <geometry>
        <mesh filename="../meshes/left_shoulder_roll_link.STL" />
      </geometry>
      <material name="">
        <color rgba="0.792156862745098 0.819607843137255 0.933333333333333 1" />
      </material>
    </visual>
    <collision>
      <origin xyz="0 0 0" rpy="0 0 0" />
      <geometry>
        <mesh filename="../meshes/left_shoulder_roll_link.STL" />
      </geometry>
    </collision>
  </link>
  <joint name="left_shoulder_roll_joint" type="revolute">
    <origin xyz="0 0.045 0" rpy="0 0 0" />
    <parent link="left_shoulder_pitch_link" />
    <child link="left_shoulder_roll_link" />
    <axis xyz="1 0 0" />
    <limit lower="-0.33" upper="3.49" effort="0" velocity="0" />
  </joint>

  <link name="left_shoulder_yaw_link">
    <inertial>
      <origin xyz="-0.00072059 0.00502361 -0.05465942" rpy="0 0 0" />
      <mass value="1.59741905" />
      <inertia ixx="0.00395265" ixy="-0.00000878" ixz="0.00004641" iyy="0.00374354" iyz="0.00013113"
        izz="0.00183857" />
    </inertial>
    <visual>
      <origin xyz="0 0 0" rpy="0 0 0" />
      <geometry>
        <mesh filename="../meshes/left_shoulder_yaw_link.STL" />
      </geometry>
      <material name="">
        <color rgba="0.792156862745098 0.819607843137255 0.933333333333333 1" />
      </material>
    </visual>
    <collision>
      <origin xyz="0 0 0" rpy="0 0 0" />
      <geometry>
        <mesh filename="../meshes/left_shoulder_yaw_link.STL" />
      </geometry>
    </collision>
  </link>
  <joint name="left_shoulder_yaw_joint" type="revolute">
    <origin xyz="1.78E-05 0 -0.1624" rpy="0 0 0" />
    <parent link="left_shoulder_roll_link" />
    <child link="left_shoulder_yaw_link" />
    <axis xyz="0 0 1" />
    <limit lower="-2.79" upper="2.79" effort="0" velocity="0" />
  </joint>

  <link name="left_elbow_link">
    <inertial>
      <origin xyz="-0.00302125 0.00253048 -0.07191958" rpy="0 0 0" />
      <mass value="1.07641157" />
      <inertia ixx="0.00263664" ixy="-0.00000430" ixz="0.00003417" iyy="0.00218298"
        iyz="-0.00005709" izz="0.00150971" />
    </inertial>
    <visual>
      <origin xyz="0 0 0" rpy="0 0 0" />
      <geometry>
        <mesh filename="../meshes/left_elbow_link.STL" />
      </geometry>
      <material name="">
        <color rgba="0.792156862745098 0.819607843137255 0.933333333333333 1" />
      </material>
    </visual>
    <collision>
      <origin xyz="0 0 0" rpy="0 0 0" />
      <geometry>
        <mesh filename="../meshes/left_elbow_link.STL" />
      </geometry>
    </collision>
  </link>
  <joint name="left_elbow_joint" type="revolute">
    <origin xyz="0 0 -0.078" rpy="0 0 0" />
    <parent link="left_shoulder_yaw_link" />
    <child link="left_elbow_link" />
    <axis xyz="0 1 0" />
    <limit lower="-1.4" upper="0.26" effort="0" velocity="0" />
  </joint>

  <link name="left_wrist_yaw_link">
    <inertial>
      <origin xyz="-0.00017266 0.01089903 -0.06147452" rpy="0 0 0" />
      <mass value="1.11070332" />
      <inertia ixx="0.00243930" ixy="0.00000331" ixz="0.00000967" iyy="0.00204462" iyz="0.00027125"
        izz="0.00116805" />
    </inertial>
    <visual>
      <origin xyz="0 0 0" rpy="0 0 0" />
      <geometry>
        <mesh filename="../meshes/left_wrist_yaw_link.STL" />
      </geometry>
      <material name="">
        <color rgba="0.792156862745098 0.819607843137255 0.933333333333333 1" />
      </material>
    </visual>
    <collision>
      <origin xyz="0 0 0" rpy="0 0 0" />
      <geometry>
        <mesh filename="../meshes/left_wrist_yaw_link.STL" />
      </geometry>
    </collision>
  </link>
  <joint name="left_wrist_yaw_joint" type="fixed">
    <origin xyz="0 0 -0.1183" rpy="0 0 0" />
    <parent link="left_elbow_link" />
    <child link="left_wrist_yaw_link" />
    <axis xyz="0 0 1" />
    <limit lower="-2.79" upper="2.79" effort="0" velocity="0" />
  </joint>

  <link name="left_wrist_pitch_link">
    <inertial>
      <origin xyz="-0.00905828 0.00237139 -0.00011361" rpy="0 0 0" />
      <mass value="0.53664475" />
      <inertia ixx="0.00040678" ixy="-0.00001159" ixz="0.00000163" iyy="0.00035228" iyz="0.00000057"
        izz="0.00040239" />
    </inertial>
    <visual>
      <origin xyz="0 0 0" rpy="0 0 0" />
      <geometry>
        <mesh filename="../meshes/left_wrist_pitch_link.STL" />
      </geometry>
      <material name="">
        <color rgba="0.792156862745098 0.819607843137255 0.933333333333333 1" />
      </material>
    </visual>
    <collision>
      <origin xyz="0 0 0" rpy="0 0 0" />
      <geometry>
        <mesh filename="../meshes/left_wrist_pitch_link.STL" />
      </geometry>
    </collision>
  </link>
  <joint name="left_wrist_pitch_joint" type="fixed">
    <origin xyz="0 0 -0.1729" rpy="0 0 0" />
    <parent link="left_wrist_yaw_link" />
    <child link="left_wrist_pitch_link" />
    <axis xyz="0 1 0" />
    <limit lower="-0.52" upper="0.52" effort="0" velocity="0" />
  </joint>

  <link name="left_wrist_roll_link">
    <inertial>
      <origin xyz="-0.00784805 0.00000131 -0.08555437" rpy="0 0 0" />
      <mass value="0.38678720" />
      <inertia ixx="0.00078769" ixy="-0.00000002" ixz="0.00004684" iyy="0.00101035" iyz="0.00000000"
        izz="0.00032330" />
    </inertial>
    <visual>
      <origin xyz="0 0 0" rpy="0 0 0" />
      <geometry>
        <mesh filename="../meshes/left_wrist_roll_link.STL" />
      </geometry>
      <material name="">
        <color rgba="0.792156862745098 0.819607843137255 0.933333333333333 1" />
      </material>
    </visual>
    <collision>
      <origin xyz="0 0 0" rpy="0 0 0" />
      <geometry>
        <mesh filename="../meshes/left_wrist_roll_link.STL" />
      </geometry>
    </collision>
  </link>
  <joint name="left_wrist_roll_joint" type="fixed">
    <origin xyz="-1.78E-05 5.1882E-05 0" rpy="0 0 0" />
    <parent link="left_wrist_pitch_link" />
    <child link="left_wrist_roll_link" />
    <axis xyz="1 0 0" />
    <limit lower="-1.57" upper="1.57" effort="0" velocity="0" />
  </joint>
  <link
    name="left_hand_base_link">
    <inertial>
      <origin
        xyz="-0.00157788568070457 -0.00034876725935859 0.0538452219801211"
        rpy="0 0 0" />
      <mass
        value="0.0672935238166485" />
      <inertia
        ixx="5.22525212160954E-05"
        ixy="3.06955729584715E-07"
        ixz="-3.90341166950521E-07"
        iyy="3.33522349207724E-05"
        iyz="-7.76680063574627E-07"
        izz="2.28469461105385E-05" />
    </inertial>
    <visual>
      <origin
        xyz="0 0 0"
        rpy="0 0 0" />
      <geometry>
        <mesh
          filename="../meshes/left_hand_base_link.STL" />
      </geometry>
      <material
        name="">
        <color
          rgba="1 1 1 1" />
      </material>
    </visual>
    <collision>
      <origin
        xyz="0 0 0"
        rpy="0 0 0" />
      <geometry>
        <mesh
          filename="../meshes/left_hand_base_link.STL" />
      </geometry>
    </collision>
  </link>
  <joint
    name="left_wrist_roll_jointfixed"
    type="fixed">
    <origin
      xyz="-0.00768 0 -0.1375"
      rpy="3.14 0 -1.57" />
    <parent
      link="left_wrist_roll_link" />
    <child
      link="left_hand_base_link" />
  </joint>
  <link
    name="left_thumb_metacarpals_base2">
    <inertial>
      <origin
        xyz="0.00162800681276937 -0.0027668017246415 -0.00184234438641236"
        rpy="0 0 0" />
      <mass
        value="0.00138588296544333" />
      <inertia
        ixx="5.26292160685909E-08"
        ixy="-3.92888681640568E-09"
        ixz="-2.43767371295222E-09"
        iyy="4.82620491570326E-08"
        iyz="3.71869784206147E-09"
        izz="2.88550286112821E-08" />
    </inertial>
    <visual>
      <origin
        xyz="0 0 0"
        rpy="0 0 0" />
      <geometry>
        <mesh
          filename="../meshes/left_thumb_metacarpals_base2.STL" />
      </geometry>
      <material
        name="">
        <color
          rgba="1 1 1 1" />
      </material>
    </visual>
    <collision>
      <origin
        xyz="0 0 0"
        rpy="0 0 0" />
      <geometry>
        <mesh
          filename="../meshes/left_thumb_metacarpals_base2.STL" />
      </geometry>
    </collision>
  </link>
  <joint
    name="left_thumb_cmc_yaw_joint"
    type="fixed">
    <origin
      xyz="0.011508 -0.022975 0.032794"
      rpy="0 0 0" />
    <parent
      link="left_hand_base_link" />
    <child
      link="left_thumb_metacarpals_base2" />
    <axis
      xyz="0 0 1" />
    <limit
      lower="0"
      upper="1.36"
      effort="100"
      velocity="1" />
  </joint>
  <link
    name="left_thumb_metacarpals">
    <inertial>
      <origin
        xyz="4.24816204999817E-05 1.74183907812875E-05 0.0228341640631254"
        rpy="0 0 0" />
      <mass
        value="0.0123381586619931" />
      <inertia
        ixx="1.10292537368909E-06"
        ixy="-5.99642232777877E-10"
        ixz="-1.14233573940545E-07"
        iyy="1.76757772551884E-06"
        iyz="-4.03963570823777E-10"
        izz="9.36347792411098E-07" />
    </inertial>
    <visual>
      <origin
        xyz="0 0 0"
        rpy="0 0 0" />
      <geometry>
        <mesh
          filename="../meshes/left_thumb_metacarpals.STL" />
      </geometry>
      <material
        name="">
        <color
          rgba="1 1 1 1" />
      </material>
    </visual>
    <collision>
      <origin
        xyz="0 0 0"
        rpy="0 0 0" />
      <geometry>
        <mesh
          filename="../meshes/left_thumb_metacarpals.STL" />
      </geometry>
    </collision>
  </link>
  <joint
    name="left_thumb_cmc_pitch_joint"
    type="fixed">
    <origin
      xyz="0.0061649 -0.010678 -0.004891"
      rpy="0 -1.1529 2.0944" />
    <parent
      link="left_thumb_metacarpals_base2" />
    <child
      link="left_thumb_metacarpals" />
    <axis
      xyz="0 1 0" />
    <limit
      lower="0"
      upper="0.58"
      effort="100"
      velocity="1" />
  </joint>
  <link
    name="left_thumb_distal">
    <inertial>
      <origin
        xyz="-0.00413725702921841 -5.90704520436747E-08 0.023011401589736"
        rpy="0 0 0" />
      <mass
        value="0.00763332957284057" />
      <inertia
        ixx="1.3057487813702E-06"
        ixy="-1.19781508112714E-11"
        ixz="-7.19551697268541E-08"
        iyy="1.2248908905341E-06"
        iyz="4.55347974652679E-12"
        izz="2.77271910592615E-07" />
    </inertial>
    <visual>
      <origin
        xyz="0 0 0"
        rpy="0 0 0" />
      <geometry>
        <mesh
          filename="../meshes/left_thumb_distal.STL" />
      </geometry>
      <material
        name="">
        <color
          rgba="1 1 1 1" />
      </material>
    </visual>
    <collision>
      <origin
        xyz="0 0 0"
        rpy="0 0 0" />
      <geometry>
        <mesh
          filename="../meshes/left_thumb_distal.STL" />
      </geometry>
    </collision>
  </link>
  <joint
    name="left_thumb_ip_joint"
    type="fixed">
    <origin
      xyz="0.0037776 0 0.045368"
      rpy="0 0 0" />
    <parent
      link="left_thumb_metacarpals" />
    <child
      link="left_thumb_distal" />
    <axis
      xyz="0 1 0" />
    <limit
      lower="0"
      upper="1.08"
      effort="100"
      velocity="1" />
    <mimic
      joint="left_thumb_cmc_pitch_joint"
      multiplier="1.86"
      offset="0" />
  </joint>
  <link
    name="left_index_proximal">
    <inertial>
      <origin
        xyz="-0.00208656556336452 2.53838713251686E-06 0.0172734941980264"
        rpy="0 0 0" />
      <mass
        value="0.00253174651934627" />
      <inertia
        ixx="2.65988714157799E-07"
        ixy="-1.67174578825824E-11"
        ixz="-4.31047725546034E-08"
        iyy="2.72914069166233E-07"
        iyz="1.8756709532167E-10"
        izz="8.56017305636748E-08" />
    </inertial>
    <visual>
      <origin
        xyz="0 0 0"
        rpy="0 0 0" />
      <geometry>
        <mesh
          filename="../meshes/left_index_proximal.STL" />
      </geometry>
      <material
        name="">
        <color
          rgba="1 1 1 1" />
      </material>
    </visual>
    <collision>
      <origin
        xyz="0 0 0"
        rpy="0 0 0" />
      <geometry>
        <mesh
          filename="../meshes/left_index_proximal.STL" />
      </geometry>
    </collision>
  </link>
  <joint
    name="left_index_mcp_pitch_joint"
    type="fixed">
    <origin
      xyz="0.0024758 -0.02419 0.098779"
      rpy="0.05236 0 0" />
    <parent
      link="left_hand_base_link" />
    <child
      link="left_index_proximal" />
    <axis
      xyz="0 1 0" />
    <limit
      lower="0"
      upper="1.60"
      effort="100"
      velocity="1" />
  </joint>
  <link
    name="left_index_distal">
    <inertial>
      <origin
        xyz="0.00658986616416549 5.13855642059191E-06 0.0194393600039178"
        rpy="0 0 0" />
      <mass
        value="0.00376951085886838" />
      <inertia
        ixx="3.22347106085043E-07"
        ixy="1.3801788663582E-11"
        ixz="1.14352857317951E-07"
        iyy="3.65328133721509E-07"
        iyz="-2.11505011705634E-10"
        izz="1.24287996386442E-07" />
    </inertial>
    <visual>
      <origin
        xyz="0 0 0"
        rpy="0 0 0" />
      <geometry>
        <mesh
          filename="../meshes/left_index_distal.STL" />
      </geometry>
      <material
        name="">
        <color
          rgba="1 1 1 1" />
      </material>
    </visual>
    <collision>
      <origin
        xyz="0 0 0"
        rpy="0 0 0" />
      <geometry>
        <mesh
          filename="../meshes/left_index_distal.STL" />
      </geometry>
    </collision>
  </link>
  <joint
    name="left_index_dip_joint"
    type="fixed">
    <origin
      xyz="-0.0052516 0 0.036625"
      rpy="0 0 0" />
    <parent
      link="left_index_proximal" />
    <child
      link="left_index_distal" />
    <axis
      xyz="0 1 0" />
    <limit
      lower="0"
      upper="1.43"
      effort="100"
      velocity="1" />
    <mimic
      joint="left_index_mcp_pitch_joint"
      multiplier="0.89"
      offset="0" />
  </joint>
  <link
    name="left_middle_proximal">
    <inertial>
      <origin
        xyz="-0.00208660654138235 2.56918180119303E-06 0.0172735011723351"
        rpy="0 0 0" />
      <mass
        value="0.00253177375206983" />
      <inertia
        ixx="2.65989021304483E-07"
        ixy="-1.69816046635662E-11"
        ixz="-4.31046683215273E-08"
        iyy="2.72914402745606E-07"
        iyz="1.87484652324395E-10"
        izz="8.5602213431865E-08" />
    </inertial>
    <visual>
      <origin
        xyz="0 0 0"
        rpy="0 0 0" />
      <geometry>
        <mesh
          filename="../meshes/left_middle_proximal.STL" />
      </geometry>
      <material
        name="">
        <color
          rgba="1 1 1 1" />
      </material>
    </visual>
    <collision>
      <origin
        xyz="0 0 0"
        rpy="0 0 0" />
      <geometry>
        <mesh
          filename="../meshes/left_middle_proximal.STL" />
      </geometry>
    </collision>
  </link>
  <joint
    name="left_middle_mcp_pitch_joint"
    type="fixed">
    <origin
      xyz="0.00052576 -0.00634 0.1027"
      rpy="0 0 0" />
    <parent
      link="left_hand_base_link" />
    <child
      link="left_middle_proximal" />
    <axis
      xyz="0 1 0" />
    <limit
      lower="0"
      upper="1.60"
      effort="100"
      velocity="1" />
  </joint>
  <link
    name="left_middle_distal">
    <inertial>
      <origin
        xyz="0.00658986516319194 5.10862924271716E-06 0.0194393315699782"
        rpy="0 0 0" />
      <mass
        value="0.00376952789210256" />
      <inertia
        ixx="3.22348591068053E-07"
        ixy="1.37122394856588E-11"
        ixz="1.1435291391668E-07"
        iyy="3.65329535087755E-07"
        iyz="-2.10453810291991E-10"
        izz="1.24288425862546E-07" />
    </inertial>
    <visual>
      <origin
        xyz="0 0 0"
        rpy="0 0 0" />
      <geometry>
        <mesh
          filename="../meshes/left_middle_distal.STL" />
      </geometry>
      <material
        name="">
        <color
          rgba="1 1 1 1" />
      </material>
    </visual>
    <collision>
      <origin
        xyz="0 0 0"
        rpy="0 0 0" />
      <geometry>
        <mesh
          filename="../meshes/left_middle_distal.STL" />
      </geometry>
    </collision>
  </link>
  <joint
    name="left_middle_dip_joint"
    type="fixed">
    <origin
      xyz="-0.0052516 0 0.036625"
      rpy="0 0 0" />
    <parent
      link="left_middle_proximal" />
    <child
      link="left_middle_distal" />
    <axis
      xyz="0 1 0" />
    <limit
      lower="0"
      upper="1.43"
      effort="100"
      velocity="1" />
    <mimic
      joint="left_middle_mcp_pitch_joint"
      multiplier="0.89"
      offset="0" />
  </joint>
  <link
    name="left_ring_proximal">
    <inertial>
      <origin
        xyz="-0.00208667931345812 2.63000419462034E-06 0.0172734926448377"
        rpy="0 0 0" />
      <mass
        value="0.00253182223645066" />
      <inertia
        ixx="2.65989756076584E-07"
        ixy="-1.74912952703656E-11"
        ixz="-4.31043325594253E-08"
        iyy="2.7291510093393E-07"
        iyz="1.87158326740895E-10"
        izz="8.56031522765909E-08" />
    </inertial>
    <visual>
      <origin
        xyz="0 0 0"
        rpy="0 0 0" />
      <geometry>
        <mesh
          filename="../meshes/left_ring_proximal.STL" />
      </geometry>
      <material
        name="">
        <color
          rgba="1 1 1 1" />
      </material>
    </visual>
    <collision>
      <origin
        xyz="0 0 0"
        rpy="0 0 0" />
      <geometry>
        <mesh
          filename="../meshes/left_ring_proximal.STL" />
      </geometry>
    </collision>
  </link>
  <joint
    name="left_ring_mcp_pitch_joint"
    type="fixed">
    <origin
      xyz="0.0010258 0.011135 0.098767"
      rpy="-0.05236 0 0" />
    <parent
      link="left_hand_base_link" />
    <child
      link="left_ring_proximal" />
    <axis
      xyz="0 1 0" />
    <limit
      lower="0"
      upper="1.60"
      effort="100"
      velocity="1" />
  </joint>
  <link
    name="left_ring_distal">
    <inertial>
      <origin
        xyz="0.00658986648895491 5.05883528165163E-06 0.019439397215532"
        rpy="0 0 0" />
      <mass
        value="0.00376949588316609" />
      <inertia
        ixx="3.2234524157181E-07"
        ixy="1.35766976056011E-11"
        ixz="1.14353011012842E-07"
        iyy="3.65326570102147E-07"
        iyz="-2.08672149138738E-10"
        izz="1.24287770218135E-07" />
    </inertial>
    <visual>
      <origin
        xyz="0 0 0"
        rpy="0 0 0" />
      <geometry>
        <mesh
          filename="../meshes/left_ring_distal.STL" />
      </geometry>
      <material
        name="">
        <color
          rgba="1 1 1 1" />
      </material>
    </visual>
    <collision>
      <origin
        xyz="0 0 0"
        rpy="0 0 0" />
      <geometry>
        <mesh
          filename="../meshes/left_ring_distal.STL" />
      </geometry>
    </collision>
  </link>
  <joint
    name="left_ring_dip_joint"
    type="fixed">
    <origin
      xyz="-0.0052516 0 0.036625"
      rpy="0 0 0" />
    <parent
      link="left_ring_proximal" />
    <child
      link="left_ring_distal" />
    <axis
      xyz="0 1 0" />
    <limit
      lower="0"
      upper="1.43"
      effort="100"
      velocity="1" />
    <mimic
      joint="left_ring_mcp_pitch_joint"
      multiplier="0.89"
      offset="0" />
  </joint>
  <link
    name="left_pinky_proximal">
    <inertial>
      <origin
        xyz="-0.00208673599799501 2.68062251165824E-06 0.0172734848131236"
        rpy="0 0 0" />
      <mass
        value="0.00253185993162408" />
      <inertia
        ixx="2.6599033687183E-07"
        ixy="-1.79030790016555E-11"
        ixz="-4.31040829565781E-08"
        iyy="2.72915617381577E-07"
        iyz="1.86906787420486E-10"
        izz="8.56039175034871E-08" />
    </inertial>
    <visual>
      <origin
        xyz="0 0 0"
        rpy="0 0 0" />
      <geometry>
        <mesh
          filename="../meshes/left_pinky_proximal.STL" />
      </geometry>
      <material
        name="">
        <color
          rgba="1 1 1 1" />
      </material>
    </visual>
    <collision>
      <origin
        xyz="0 0 0"
        rpy="0 0 0" />
      <geometry>
        <mesh
          filename="../meshes/left_pinky_proximal.STL" />
      </geometry>
    </collision>
  </link>
  <joint
    name="left_pinky_mcp_pitch_joint"
    type="fixed">
    <origin
      xyz="0.0024758 0.028372 0.092741"
      rpy="-0.087266 0 0" />
    <parent
      link="left_hand_base_link" />
    <child
      link="left_pinky_proximal" />
    <axis
      xyz="0 1 0" />
    <limit
      lower="0"
      upper="1.60"
      effort="100"
      velocity="1" />
  </joint>
  <link
    name="left_pinky_distal">
    <inertial>
      <origin
        xyz="0.00658987588903027 5.03087534178825E-06 0.0194394491065091"
        rpy="0 0 0" />
      <mass
        value="0.00376948071276134" />
      <inertia
        ixx="3.22343583730488E-07"
        ixy="1.35768173270357E-11"
        ixz="1.14353289593012E-07"
        iyy="3.65325180884183E-07"
        iyz="-2.0744198062439E-10"
        izz="1.24287567374229E-07" />
    </inertial>
    <visual>
      <origin
        xyz="0 0 0"
        rpy="0 0 0" />
      <geometry>
        <mesh
          filename="../meshes/left_pinky_distal.STL" />
      </geometry>
      <material
        name="">
        <color
          rgba="1 1 1 1" />
      </material>
    </visual>
    <collision>
      <origin
        xyz="0 0 0"
        rpy="0 0 0" />
      <geometry>
        <mesh
          filename="../meshes/left_pinky_distal.STL" />
      </geometry>
    </collision>
  </link>
  <joint
    name="left_pinky_dip_joint"
    type="fixed">
    <origin
      xyz="-0.0052516 0 0.036625"
      rpy="0 0 0" />
    <parent
      link="left_pinky_proximal" />
    <child
      link="left_pinky_distal" />
    <axis
      xyz="0 1 0" />
    <limit
      lower="0"
      upper="1.43"
      effort="100"
      velocity="1" />
    <mimic
      joint="left_pinky_mcp_pitch_joint"
      multiplier="0.89"
      offset="0" />
  </joint>
  <link name="right_shoulder_pitch_link">
    <inertial>
      <origin xyz="0.00707468 -0.03563844 0.00010527" rpy="0 0 0" />
      <mass value="1.98203402" />
      <inertia ixx="0.00322395" ixy="0.00014288" ixz="0.00002189" iyy="0.00282214" iyz="-0.00003820"
        izz="0.00344885" />
    </inertial>
    <visual>
      <origin xyz="0 0 0" rpy="0 0 0" />
      <geometry>
        <mesh filename="../meshes/right_shoulder_pitch_link.STL" />
      </geometry>
      <material name="">
        <color rgba="0.898039215686275 0.917647058823529 0.929411764705882 1" />
      </material>
    </visual>
    <collision>
      <origin xyz="0 0 0" rpy="0 0 0" />
      <geometry>
        <mesh filename="../meshes/right_shoulder_pitch_link.STL" />
      </geometry>
    </collision>
  </link>
  <joint name="right_shoulder_pitch_joint" type="revolute">
    <origin xyz="0.0 -0.2153 0.61575" rpy="0 0 0" />
    <parent link="pelvis" />
    <child link="right_shoulder_pitch_link" />
    <axis xyz="0 1 0" />
    <limit lower="-2.79" upper="2.79" effort="0" velocity="0" />
  </joint>

  <link name="right_shoulder_roll_link">
    <inertial>
      <origin xyz="0.00378470 -0.00156751 -0.08524291" rpy="0 0 0" />
      <mass value="1.58847867" />
      <inertia ixx="0.00406250" ixy="-0.00000596" ixz="-0.00042592" iyy="0.00490028"
        iyz="-0.00003699" izz="0.00281066" />
    </inertial>
    <visual>
      <origin xyz="0 0 0" rpy="0 0 0" />
      <geometry>
        <mesh filename="../meshes/right_shoulder_roll_link.STL" />
      </geometry>
      <material name="">
        <color rgba="1 1 1 1" />
      </material>
    </visual>
    <collision>
      <origin xyz="0 0 0" rpy="0 0 0" />
      <geometry>
        <mesh filename="../meshes/right_shoulder_roll_link.STL" />
      </geometry>
    </collision>
  </link>
  <joint name="right_shoulder_roll_joint" type="revolute">
    <origin xyz="0 -0.045 0" rpy="0 0 0" />
    <parent link="right_shoulder_pitch_link" />
    <child link="right_shoulder_roll_link" />
    <axis xyz="1 0 0" />
    <limit lower="-3.49" upper="0.33" effort="0" velocity="0" />
  </joint>

  <link name="right_shoulder_yaw_link">
    <inertial>
      <origin xyz="-0.00072031 -0.00502348 -0.05477962" rpy="0 0 0" />
      <mass value="1.59741905" />
      <inertia ixx="0.00396187" ixy="0.00000873" ixz="0.00005052" iyy="0.00375300" iyz="-0.00012526"
        izz="0.00183871" />
    </inertial>
    <visual>
      <origin xyz="0 0 0" rpy="0 0 0" />
      <geometry>
        <mesh filename="../meshes/right_shoulder_yaw_link.STL" />
      </geometry>
      <material name="">
        <color rgba="0.792156862745098 0.819607843137255 0.933333333333333 1" />
      </material>
    </visual>
    <collision>
      <origin xyz="0 0 0" rpy="0 0 0" />
      <geometry>
        <mesh filename="../meshes/right_shoulder_yaw_link.STL" />
      </geometry>
    </collision>
  </link>
  <joint name="right_shoulder_yaw_joint" type="revolute">
    <origin xyz="1.78E-05 0 -0.1624" rpy="0 0 0" />
    <parent link="right_shoulder_roll_link" />
    <child link="right_shoulder_yaw_link" />
    <axis xyz="0 0 1" />
    <limit lower="-2.79" upper="2.79" effort="0" velocity="0" />
  </joint>

  <link name="right_elbow_link">
    <inertial>
      <origin xyz="-0.00302125 -0.00253048 -0.07191958" rpy="0 0 0" />
      <mass value="1.07641157" />
      <inertia ixx="0.00263664" ixy="0.00000430" ixz="0.00003417" iyy="0.00218298" iyz="0.00005709"
        izz="0.00150971" />
    </inertial>
    <visual>
      <origin xyz="0 0 0" rpy="0 0 0" />
      <geometry>
        <mesh filename="../meshes/right_elbow_link.STL" />
      </geometry>
      <material name="">
        <color rgba="0.792156862745098 0.819607843137255 0.933333333333333 1" />
      </material>
    </visual>
    <collision>
      <origin xyz="0 0 0" rpy="0 0 0" />
      <geometry>
        <mesh filename="../meshes/right_elbow_link.STL" />
      </geometry>
    </collision>
  </link>
  <joint name="right_elbow_joint" type="revolute">
    <origin xyz="0 0 -0.078" rpy="0 0 0" />
    <parent link="right_shoulder_yaw_link" />
    <child link="right_elbow_link" />
    <axis xyz="0 1 0" />
    <limit lower="-1.4" upper="0.26" effort="0" velocity="0" />
  </joint>

  <link name="right_wrist_yaw_link">
    <inertial>
      <origin xyz="-0.00017266 -0.01089903 -0.06147452" rpy="0 0 0" />
      <mass value="1.11070332" />
      <inertia ixx="0.00243930" ixy="-0.00000331" ixz="0.00000967" iyy="0.00204462"
        iyz="-0.00027125" izz="0.00116805" />
    </inertial>
    <visual>
      <origin xyz="0 0 0" rpy="0 0 0" />
      <geometry>
        <mesh filename="../meshes/right_wrist_yaw_link.STL" />
      </geometry>
      <material name="">
        <color rgba="0.792156862745098 0.819607843137255 0.933333333333333 1" />
      </material>
    </visual>
    <collision>
      <origin xyz="0 0 0" rpy="0 0 0" />
      <geometry>
        <mesh filename="../meshes/right_wrist_yaw_link.STL" />
      </geometry>
    </collision>
  </link>
  <joint name="right_wrist_yaw_joint" type="fixed">
    <origin xyz="0 0 -0.1183" rpy="0 0 0" />
    <parent link="right_elbow_link" />
    <child link="right_wrist_yaw_link" />
    <axis xyz="0 0 1" />
    <limit lower="-2.79" upper="2.79" effort="0" velocity="0" />
  </joint>

  <link name="right_wrist_pitch_link">
    <inertial>
      <origin xyz="-0.00905828 -0.00237139 -0.00011361" rpy="0 0 0" />
      <mass value="0.53664475" />
      <inertia ixx="0.00040678" ixy="0.00001159" ixz="0.00000163" iyy="0.00035228" iyz="-0.00000057"
        izz="0.00040239" />
    </inertial>
    <visual>
      <origin xyz="0 0 0" rpy="0 0 0" />
      <geometry>
        <mesh filename="../meshes/right_wrist_pitch_link.STL" />
      </geometry>
      <material name="">
        <color rgba="0.792156862745098 0.819607843137255 0.933333333333333 1" />
      </material>
    </visual>
    <collision>
      <origin xyz="0 0 0" rpy="0 0 0" />
      <geometry>
        <mesh filename="../meshes/right_wrist_pitch_link.STL" />
      </geometry>
    </collision>
  </link>
  <joint name="right_wrist_pitch_joint" type="fixed">
    <origin xyz="0 0 -0.1729" rpy="0 0 0" />
    <parent link="right_wrist_yaw_link" />
    <child link="right_wrist_pitch_link" />
    <axis xyz="0 1 0" />
    <limit lower="-0.52" upper="0.52" effort="0" velocity="0" />
  </joint>

  <link name="right_wrist_roll_link">
    <inertial>
      <origin xyz="-0.00784805 -0.00000131 -0.08555437" rpy="0 0 0" />
      <mass value="0.38678720" />
      <inertia ixx="0.00078769" ixy="0.00000002" ixz="0.00004684" iyy="0.00101035" iyz="0.00000000"
        izz="0.00032330" />
    </inertial>
    <visual>
      <origin xyz="0 0 0" rpy="0 0 0" />
      <geometry>
        <mesh filename="../meshes/right_wrist_roll_link.STL" />
      </geometry>
      <material name="">
        <color rgba="0.792156862745098 0.819607843137255 0.933333333333333 1" />
      </material>
    </visual>
    <collision>
      <origin xyz="0 0 0" rpy="0 0 0" />
      <geometry>
        <mesh filename="../meshes/right_wrist_roll_link.STL" />
      </geometry>
    </collision>
  </link>
  <joint name="right_wrist_roll_joint" type="fixed">
    <origin xyz="-1.78E-05 5.1882E-05 0" rpy="0 0 0" />
    <parent link="right_wrist_pitch_link" />
    <child link="right_wrist_roll_link" />
    <axis xyz="1 0 0" />
    <limit lower="-1.57" upper="1.57" effort="0" velocity="0" />
  </joint>
  <link
    name="right_hand_base_link">
    <inertial>
      <origin
        xyz="-0.00160320773490556 0.000358462699237561 0.0538002704027215"
        rpy="0 0 0" />
      <mass
        value="0.06740077960995" />
      <inertia
        ixx="5.22359941041901E-05"
        ixy="3.0391535852764E-07"
        ixz="3.88322215371643E-07"
        iyy="3.33473043513648E-05"
        iyz="-7.77555280794861E-07"
        izz="2.28342677422006E-05" />
    </inertial>
    <visual>
      <origin
        xyz="0 0 0"
        rpy="0 0 0" />
      <geometry>
        <mesh
          filename="../meshes/right_hand_base_link.STL" />
      </geometry>
      <material
        name="">
        <color
          rgba="1 0.6 0 1" />
      </material>
    </visual>
    <collision>
      <origin
        xyz="0 0 0"
        rpy="0 0 0" />
      <geometry>
        <mesh
          filename="../meshes/right_hand_base_link.STL" />
      </geometry>
    </collision>
  </link>
  <joint
    name="right_wrist_roll_jointfixed"
    type="fixed">
    <origin
      xyz="-0.00768 0 -0.1375"
      rpy="3.14 0 1.57" />
    <parent
      link="right_wrist_roll_link" />
    <child
      link="right_hand_base_link" />
  </joint>
  <link
    name="right_thumb_metacarpals_base2">
    <inertial>
      <origin
        xyz="0.00162795738393507 0.00276671978336815 -0.00184227725602707"
        rpy="0 0 0" />
      <mass
        value="0.00138591070212997" />
      <inertia
        ixx="5.26294625624223E-08"
        ixy="-3.9288013799604E-09"
        ixz="2.43766268199571E-09"
        iyy="4.82623724532942E-08"
        iyz="3.71867754115443E-09"
        izz="2.88555522060562E-08" />
    </inertial>
    <visual>
      <origin
        xyz="0 0 0"
        rpy="0 0 0" />
      <geometry>
        <mesh
          filename="../meshes/right_thumb_metacarpals_base2.STL" />
      </geometry>
      <material
        name="">
        <color
          rgba="0.164705882352941 0.282352941176471 0.443137254901961 1" />
      </material>
    </visual>
    <collision>
      <origin
        xyz="0 0 0"
        rpy="0 0 0" />
      <geometry>
        <mesh
          filename="../meshes/right_thumb_metacarpals_base2.STL" />
      </geometry>
    </collision>
  </link>
  <joint
    name="right_thumb_cmc_yaw_joint"
    type="fixed">
    <origin
      xyz="0.011508 0.022975 0.032794"
      rpy="0 0 0" />
    <parent
      link="right_hand_base_link" />
    <child
      link="right_thumb_metacarpals_base2" />
    <axis
      xyz="0 0 -1" />
    <limit
      lower="0"
      upper="1.36"
      effort="100"
      velocity="1" />
  </joint>
  <link
    name="right_thumb_metacarpals">
    <inertial>
      <origin
        xyz="4.24920612856275E-05 -1.67885666835232E-05 0.0228341522590467"
        rpy="0 0 0" />
      <mass
        value="0.0123381607727595" />
      <inertia
        ixx="1.10292488693766E-06"
        ixy="-6.14241939151719E-10"
        ixz="1.14233108676795E-07"
        iyy="1.76757658485787E-06"
        iyz="-4.24576599367025E-10"
        izz="9.36348143657406E-07" />
    </inertial>
    <visual>
      <origin
        xyz="0 0 0"
        rpy="0 0 0" />
      <geometry>
        <mesh
          filename="../meshes/right_thumb_metacarpals.STL" />
      </geometry>
      <material
        name="">
        <color
          rgba="1 0.6 0 1" />
      </material>
    </visual>
    <collision>
      <origin
        xyz="0 0 0"
        rpy="0 0 0" />
      <geometry>
        <mesh
          filename="../meshes/right_thumb_metacarpals.STL" />
      </geometry>
    </collision>
  </link>
  <joint
    name="right_thumb_cmc_pitch_joint"
    type="fixed">
    <origin
      xyz="0.0061649 0.010678 -0.004891"
      rpy="0 -1.1529 -2.0944" />
    <parent
      link="right_thumb_metacarpals_base2" />
    <child
      link="right_thumb_metacarpals" />
    <axis
      xyz="0 1 0" />
    <limit
      lower="0"
      upper="0.58"
      effort="100"
      velocity="1" />
  </joint>
  <link
    name="right_thumb_distal">
    <inertial>
      <origin
        xyz="-0.00413690727496815 -4.54842793429222E-07 0.0230097179163771"
        rpy="0 0 0" />
      <mass
        value="0.00763302603723749" />
      <inertia
        ixx="1.30546842791578E-06"
        ixy="-2.61617511029467E-12"
        ixz="7.19030685242407E-08"
        iyy="1.22457212713176E-06"
        iyz="1.66931068485225E-11"
        izz="2.7729897944409E-07" />
    </inertial>
    <visual>
      <origin
        xyz="0 0 0"
        rpy="0 0 0" />
      <geometry>
        <mesh
          filename="../meshes/right_thumb_distal.STL" />
      </geometry>
      <material
        name="">
        <color
          rgba="0.792156862745098 0.792156862745098 0.792156862745098 1" />
      </material>
    </visual>
    <collision>
      <origin
        xyz="0 0 0"
        rpy="0 0 0" />
      <geometry>
        <mesh
          filename="../meshes/right_thumb_distal.STL" />
      </geometry>
    </collision>
  </link>
  <joint
    name="right_thumb_ip_joint"
    type="fixed">
    <origin
      xyz="0.0037776 0 0.045368"
      rpy="0 0 0" />
    <parent
      link="right_thumb_metacarpals" />
    <child
      link="right_thumb_distal" />
    <axis
      xyz="0 1 0" />
    <limit
      lower="0"
      upper="1.08"
      effort="100"
      velocity="1" />
    <mimic
      joint="right_thumb_cmc_pitch_joint"
      multiplier="1.86"
      offset="0" />
  </joint>
  <link
    name="right_index_proximal">
    <inertial>
      <origin
        xyz="-0.00208665596033792 -4.8964990644329E-06 0.0172736718900068"
        rpy="0 0 0" />
      <mass
        value="0.00253178529301663" />
      <inertia
        ixx="2.65990159539482E-07"
        ixy="-3.55165625722842E-11"
        ixz="4.31046335852167E-08"
        iyy="2.72915460277804E-07"
        iyz="1.75935978708959E-10"
        izz="8.56026306687528E-08" />
    </inertial>
    <visual>
      <origin
        xyz="0 0 0"
        rpy="0 0 0" />
      <geometry>
        <mesh
          filename="../meshes/right_index_proximal.STL" />
      </geometry>
      <material
        name="">
        <color
          rgba="0.980392156862745 0.780392156862745 0.627450980392157 1" />
      </material>
    </visual>
    <collision>
      <origin
        xyz="0 0 0"
        rpy="0 0 0" />
      <geometry>
        <mesh
          filename="../meshes/right_index_proximal.STL" />
      </geometry>
    </collision>
  </link>
  <joint
    name="right_index_mcp_pitch_joint"
    type="fixed">
    <origin
      xyz="0.0024758 0.02419 0.098779"
      rpy="-0.05236 0 0" />
    <parent
      link="right_hand_base_link" />
    <child
      link="right_index_proximal" />
    <axis
      xyz="0 1 0" />
    <limit
      lower="0"
      upper="1.60"
      effort="100"
      velocity="1" />
  </joint>
  <link
    name="right_index_distal">
    <inertial>
      <origin
        xyz="0.00658940011630532 -4.59976557022623E-06 0.0194434136420913"
        rpy="0 0 0" />
      <mass
        value="0.00376787129082313" />
      <inertia
        ixx="3.22116619426455E-07"
        ixy="1.03152735699049E-11"
        ixz="-1.14363506430985E-07"
        iyy="3.65131844686317E-07"
        iyz="-1.97263639269362E-10"
        izz="1.24256890612907E-07" />
    </inertial>
    <visual>
      <origin
        xyz="0 0 0"
        rpy="0 0 0" />
      <geometry>
        <mesh
          filename="../meshes/right_index_distal.STL" />
      </geometry>
      <material
        name="">
        <color
          rgba="0.164705882352941 0.282352941176471 0.443137254901961 1" />
      </material>
    </visual>
    <collision>
      <origin
        xyz="0 0 0"
        rpy="0 0 0" />
      <geometry>
        <mesh
          filename="../meshes/right_index_distal.STL" />
      </geometry>
    </collision>
  </link>
  <joint
    name="right_index_dip_joint"
    type="fixed">
    <origin
      xyz="-0.0052516 0 0.036625"
      rpy="0 0 0" />
    <parent
      link="right_index_proximal" />
    <child
      link="right_index_distal" />
    <axis
      xyz="0 1 0" />
    <limit
      lower="0"
      upper="1.43"
      effort="100"
      velocity="1" />
    <mimic
      joint="right_index_mcp_pitch_joint"
      multiplier="0.89"
      offset="0" />
  </joint>
  <link
    name="right_middle_proximal">
    <inertial>
      <origin
        xyz="-0.00208661081773556 -4.93451838476378E-06 0.0172736805321904"
        rpy="0 0 0" />
      <mass
        value="0.00253175497594429" />
      <inertia
        ixx="2.65989683690695E-07"
        ixy="-3.58343951791586E-11"
        ixz="4.31048601085216E-08"
        iyy="2.72915006047006E-07"
        iyz="1.75718024412593E-10"
        izz="8.56020467202518E-08" />
    </inertial>
    <visual>
      <origin
        xyz="0 0 0"
        rpy="0 0 0" />
      <geometry>
        <mesh
          filename="../meshes/right_middle_proximal.STL" />
      </geometry>
      <material
        name="">
        <color
          rgba="0.164705882352941 0.282352941176471 0.443137254901961 1" />
      </material>
    </visual>
    <collision>
      <origin
        xyz="0 0 0"
        rpy="0 0 0" />
      <geometry>
        <mesh
          filename="../meshes/right_middle_proximal.STL" />
      </geometry>
    </collision>
  </link>
  <joint
    name="right_middle_mcp_pitch_joint"
    type="fixed">
    <origin
      xyz="0.00052576 0.00634 0.1027"
      rpy="0 0 0" />
    <parent
      link="right_hand_base_link" />
    <child
      link="right_middle_proximal" />
    <axis
      xyz="0 1 0" />
    <limit
      lower="0"
      upper="1.60"
      effort="100"
      velocity="1" />
  </joint>
  <link
    name="right_middle_distal">
    <inertial>
      <origin
        xyz="0.00658940304809306 -4.5885743593238E-06 0.0194434523296449"
        rpy="0 0 0" />
      <mass
        value="0.00376786259758948" />
      <inertia
        ixx="3.221153658306E-07"
        ixy="1.02639617308432E-11"
        ixz="-1.14363547272711E-07"
        iyy="3.65130723083104E-07"
        iyz="-1.96904618797577E-10"
        izz="1.24256787913797E-07" />
    </inertial>
    <visual>
      <origin
        xyz="0 0 0"
        rpy="0 0 0" />
      <geometry>
        <mesh
          filename="../meshes/right_middle_distal.STL" />
      </geometry>
      <material
        name="">
        <color
          rgba="0.164705882352941 0.282352941176471 0.443137254901961 1" />
      </material>
    </visual>
    <collision>
      <origin
        xyz="0 0 0"
        rpy="0 0 0" />
      <geometry>
        <mesh
          filename="../meshes/right_middle_distal.STL" />
      </geometry>
    </collision>
  </link>
  <joint
    name="right_middle_dip_joint"
    type="fixed">
    <origin
      xyz="-0.0052516 0 0.036625"
      rpy="0 0 0" />
    <parent
      link="right_middle_proximal" />
    <child
      link="right_middle_distal" />
    <axis
      xyz="0 1 0" />
    <limit
      lower="0"
      upper="1.43"
      effort="100"
      velocity="1" />
    <mimic
      joint="right_middle_mcp_pitch_joint"
      multiplier="0.89"
      offset="0" />
  </joint>
  <link
    name="right_ring_proximal">
    <inertial>
      <origin
        xyz="-0.00208654311325356 -4.98538564003281E-06 0.0172736743497407"
        rpy="0 0 0" />
      <mass
        value="0.00253170963529411" />
      <inertia
        ixx="2.6598913795678E-07"
        ixy="-3.62757108675266E-11"
        ixz="4.31050611555507E-08"
        iyy="2.72914417061517E-07"
        iyz="1.75554984053478E-10"
        izz="8.56012458677515E-08" />
    </inertial>
    <visual>
      <origin
        xyz="0 0 0"
        rpy="0 0 0" />
      <geometry>
        <mesh
          filename="../meshes/right_ring_proximal.STL" />
      </geometry>
      <material
        name="">
        <color
          rgba="0.980392156862745 0.780392156862745 0.627450980392157 1" />
      </material>
    </visual>
    <collision>
      <origin
        xyz="0 0 0"
        rpy="0 0 0" />
      <geometry>
        <mesh
          filename="../meshes/right_ring_proximal.STL" />
      </geometry>
    </collision>
  </link>
  <joint
    name="right_ring_mcp_pitch_joint"
    type="fixed">
    <origin
      xyz="0.0010258 -0.011135 0.098767"
      rpy="0.05236 0 0" />
    <parent
      link="right_hand_base_link" />
    <child
      link="right_ring_proximal" />
    <axis
      xyz="0 1 0" />
    <limit
      lower="0"
      upper="1.60"
      effort="100"
      velocity="1" />
  </joint>
  <link
    name="right_ring_distal">
    <inertial>
      <origin
        xyz="0.00658940273069729 -4.56628863591824E-06 0.0194435005686854"
        rpy="0 0 0" />
      <mass
        value="0.0037678395356105" />
      <inertia
        ixx="3.22112632437858E-07"
        ixy="1.01848408913558E-11"
        ixz="-1.1436348915342E-07"
        iyy="3.65128262095686E-07"
        iyz="-1.96145632992445E-10"
        izz="1.24256284608064E-07" />
    </inertial>
    <visual>
      <origin
        xyz="0 0 0"
        rpy="0 0 0" />
      <geometry>
        <mesh
          filename="../meshes/right_ring_distal.STL" />
      </geometry>
      <material
        name="">
        <color
          rgba="0.164705882352941 0.282352941176471 0.443137254901961 1" />
      </material>
    </visual>
    <collision>
      <origin
        xyz="0 0 0"
        rpy="0 0 0" />
      <geometry>
        <mesh
          filename="../meshes/right_ring_distal.STL" />
      </geometry>
    </collision>
  </link>
  <joint
    name="right_ring_dip_joint"
    type="fixed">
    <origin
      xyz="-0.0052516 0 0.036625"
      rpy="0 0 0" />
    <parent
      link="right_ring_proximal" />
    <child
      link="right_ring_distal" />
    <axis
      xyz="0 1 0" />
    <limit
      lower="0"
      upper="1.43"
      effort="100"
      velocity="1" />
    <mimic
      joint="right_ring_mcp_pitch_joint"
      multiplier="0.89"
      offset="0" />
  </joint>
  <link
    name="right_pinky_proximal">
    <inertial>
      <origin
        xyz="-0.00208649034130813 -5.02314582560837E-06 0.0172736680793697"
        rpy="0 0 0" />
      <mass
        value="0.00253167400540778" />
      <inertia
        ixx="2.65988718820404E-07"
        ixy="-3.66012295280295E-11"
        ixz="4.31052220484445E-08"
        iyy="2.72913936904813E-07"
        iyz="1.75447396222308E-10"
        izz="8.56006424720129E-08" />
    </inertial>
    <visual>
      <origin
        xyz="0 0 0"
        rpy="0 0 0" />
      <geometry>
        <mesh
          filename="../meshes/right_pinky_proximal.STL" />
      </geometry>
      <material
        name="">
        <color
          rgba="0.980392156862745 0.780392156862745 0.627450980392157 1" />
      </material>
    </visual>
    <collision>
      <origin
        xyz="0 0 0"
        rpy="0 0 0" />
      <geometry>
        <mesh
          filename="../meshes/right_pinky_proximal.STL" />
      </geometry>
    </collision>
  </link>
  <joint
    name="right_pinky_mcp_pitch_joint"
    type="fixed">
    <origin
      xyz="0.0024758 -0.028372 0.092741"
      rpy="0.087266 0 0" />
    <parent
      link="right_hand_base_link" />
    <child
      link="right_pinky_proximal" />
    <axis
      xyz="0 1 0" />
    <limit
      lower="0"
      upper="1.60"
      effort="100"
      velocity="1" />
  </joint>
  <link
    name="right_pinky_distal">
    <inertial>
      <origin
        xyz="0.00658940431519205 -4.55268314210333E-06 0.0194435341098305"
        rpy="0 0 0" />
      <mass
        value="0.00376782669873412" />
      <inertia
        ixx="3.22111112339498E-07"
        ixy="1.01707985908333E-11"
        ixz="-1.14363524419061E-07"
        iyy="3.65126916899176E-07"
        iyz="-1.95589215866356E-10"
        izz="1.24256004854426E-07" />
    </inertial>
    <visual>
      <origin
        xyz="0 0 0"
        rpy="0 0 0" />
      <geometry>
        <mesh
          filename="../meshes/right_pinky_distal.STL" />
      </geometry>
      <material
        name="">
        <color
          rgba="0.164705882352941 0.282352941176471 0.443137254901961 1" />
      </material>
    </visual>
    <collision>
      <origin
        xyz="0 0 0"
        rpy="0 0 0" />
      <geometry>
        <mesh
          filename="../meshes/right_pinky_distal.STL" />
      </geometry>
    </collision>
  </link>
  <joint
    name="right_pinky_dip_joint"
    type="fixed">
    <origin
      xyz="-0.0052516 0 0.036625"
      rpy="0 0 0" />
    <parent
      link="right_pinky_proximal" />
    <child
      link="right_pinky_distal" />
    <axis
      xyz="0 1 0" />
    <limit
      lower="0"
      upper="1.43"
      effort="100"
      velocity="1" />
    <mimic
      joint="right_pinky_mcp_pitch_joint"
      multiplier="0.89"
      offset="0" />
  </joint>
</robot>